2025-04-05 19:47:03 ERROR 400 response executing GraphQL.
2025-04-05 19:47:03 ERROR {"errors":[{"message":"name required for project query","path":["project"]}],"data":{"project":null}}
2025-04-05 19:47:03 ERROR Traceback (most recent call last):
  File "C:\Users\delfi\anaconda3\envs\normal\Lib\site-packages\wandb\apis\normalize.py", line 25, in wrapper
    return func(*args, **kwargs)
           ^^^^^^^^^^^^^^^^^^^^^
  File "C:\Users\delfi\anaconda3\envs\normal\Lib\site-packages\wandb\sdk\internal\internal_api.py", line 1113, in sweep
    response = self.gql(
               ^^^^^^^^^
  File "C:\Users\delfi\anaconda3\envs\normal\Lib\site-packages\wandb\sdk\internal\internal_api.py", line 365, in gql
    ret = self._retry_gql(
          ^^^^^^^^^^^^^^^^
  File "C:\Users\delfi\anaconda3\envs\normal\Lib\site-packages\wandb\sdk\lib\retry.py", line 131, in __call__
    result = self._call_fn(*args, **kwargs)
             ^^^^^^^^^^^^^^^^^^^^^^^^^^^^^^
  File "C:\Users\delfi\anaconda3\envs\normal\Lib\site-packages\wandb\sdk\internal\internal_api.py", line 393, in execute
    return self.client.execute(*args, **kwargs)  # type: ignore
           ^^^^^^^^^^^^^^^^^^^^^^^^^^^^^^^^^^^^
  File "C:\Users\delfi\anaconda3\envs\normal\Lib\site-packages\wandb\vendor\gql-0.2.0\wandb_gql\client.py", line 52, in execute
    result = self._get_result(document, *args, **kwargs)
             ^^^^^^^^^^^^^^^^^^^^^^^^^^^^^^^^^^^^^^^^^^^
  File "C:\Users\delfi\anaconda3\envs\normal\Lib\site-packages\wandb\vendor\gql-0.2.0\wandb_gql\client.py", line 60, in _get_result
    return self.transport.execute(document, *args, **kwargs)
           ^^^^^^^^^^^^^^^^^^^^^^^^^^^^^^^^^^^^^^^^^^^^^^^^^
  File "C:\Users\delfi\anaconda3\envs\normal\Lib\site-packages\wandb\sdk\lib\gql_request.py", line 59, in execute
    request.raise_for_status()
  File "C:\Users\delfi\anaconda3\envs\normal\Lib\site-packages\requests\models.py", line 1024, in raise_for_status
    raise HTTPError(http_error_msg, response=self)
requests.exceptions.HTTPError: 400 Client Error: Bad Request for url: https://api.wandb.ai/graphql

During handling of the above exception, another exception occurred:

Traceback (most recent call last):
  File "C:\Users\delfi\anaconda3\envs\normal\Lib\site-packages\wandb\cli\cli.py", line 104, in wrapper
    return func(*args, **kwargs)
           ^^^^^^^^^^^^^^^^^^^^^
  File "C:\Users\delfi\anaconda3\envs\normal\Lib\site-packages\wandb\cli\cli.py", line 1680, in agent
    wandb_agent.agent(sweep_id, entity=entity, project=project, count=count)
  File "C:\Users\delfi\anaconda3\envs\normal\Lib\site-packages\wandb\wandb_agent.py", line 572, in agent
    return run_agent(
           ^^^^^^^^^^
  File "C:\Users\delfi\anaconda3\envs\normal\Lib\site-packages\wandb\wandb_agent.py", line 531, in run_agent
    agent.run()
  File "C:\Users\delfi\anaconda3\envs\normal\Lib\site-packages\wandb\wandb_agent.py", line 193, in run
    sweep_obj = self._api.sweep(self._sweep_id, "{}")
                ^^^^^^^^^^^^^^^^^^^^^^^^^^^^^^^^^^^^^
  File "C:\Users\delfi\anaconda3\envs\normal\Lib\site-packages\wandb\apis\internal.py", line 130, in sweep
    return self.api.sweep(*args, **kwargs)
           ^^^^^^^^^^^^^^^^^^^^^^^^^^^^^^^
  File "C:\Users\delfi\anaconda3\envs\normal\Lib\site-packages\wandb\apis\normalize.py", line 35, in wrapper
    raise CommError(message, error)
wandb.errors.errors.CommError: name required for project query (Error 400: Bad Request)

